Workbook

Sheet Runwal
C1: Runwal - Subodh | D1: Sobha
A2: Ambedkar Nagar, Worli | C2: i | D2: S | E2: p1
A3: Borla | D3: ☑
A4: Jasmine (JV/JD) | C4: x | E4: p3
A5: Khajuria Nagar | C5: o
A6: New Jal Darshan | C6: i | D6: S | E6: p2
A7: Nityanand Baug | C7: x | D7: o | E7: p3
A8: Prahlad CHSL - Santacurz | D8: o
A9: Rajendra Park & Nalanda Mall, Goregaon (West) | C9: o | E9: p3
A10: Sumer Nagar | C10: o | D10: o
A11: Tolaram | C11: i | D11: o | E11: p1
A12: Redstone, Juhu | C12: x
A13: Maker Mahal | C13: i | E13: P2
A16: Runwal Enterprises
A17: Property Name | B17: Amit jis Comment | C17: IM | D17: Location | E17: Deal Type | F17: Plot size (sq.m.) | G17: Topline (in Crores) | H17: Comment | I17: Status | J17: Lastest updated
A18: LIC Colony | B18: Interested - Get offer | C18: Send Feasibility for Offer | D18: Mulund | E18: Redevelopment | F18: 10715 | G18: 847 | H18: New Opportunity, Anex appointed as Representatives for the society | I18: New | J18: Society is actively looking to get redeveloped
A19: Manish Nagar | D19: =VLOOKUP(A19,'Opps combined list'!$C$4:$E$42,2,FALSE) -> Andheri West | E19: Society Redevelopment | F19: 10217 | G19: 1270 | H19: New Opportunity, Anex appointed as PMC for society | I19: New | J19: Society is actively looking to get redeveloped
A20: Karnatak | D20: Mahim West | E20: Society Redevelopment | F20: 5850 | G20: 852 | H20: New Opportunity, Anex pursuing appointed as PMC for society | I20: New
A21: Sea Glimpse | D21: Worli | E21: Society Redevelopment | F21: 1696 | G21: 450 | H21: New Opportunity | I21: New | J21: Society is actively looking to get redeveloped
A22: Ambedkar Nagar, Worli | D22: Worli | E22: Society Redevelopment | F22: 9311 | G22: 1481 | H22: The Group has shown interest in the opportunity, Mahesh sir has also conducted a site with Team Anex. EoI format shared | I22: Interested (P1) | J22: Society has one offer, they believe they should get a better offer and looking for potential developers
A23: Tolaram | D23: =VLOOKUP(A23,'Opps combined list'!$C$4:$E$42,2,FALSE) -> Chembur | E23: Society Redevelopment | F23: 18618 | G23: 2000 | H23: The Group has shown interest in the opportunity, Mahesh sir raised his concerns over access and buildibilty | I23: Interested (P1) | J23: Society is actively looking developers, open to one on one dealing
A24: New Jal Darshan | D24: Bandra West | E24: Society Redevelopment | F24: 2053.2 | G24: 290 | H24: The Group has shown interest in the opportunity, and will participate in the Tender | I24: Interested (P2) | J24: Private tender will be floated soon
A25: Maker Mahal | D25: =VLOOKUP(A25,'Opps combined list'!$C$4:$E$42,2,FALSE) -> Bandra West | E25: Outright | F25: 2025.9 | G25: 800 | H25: Liked the location, Mahesh sir, showed hesistance due to high outright value | I25: Interested (P2) | J25: Last offer from Mahindra at 235 cr. is being evaluated
A26: Jasmine (JV/JD) | D26: Colaba | E26: JV/JD | F26: 1270.91 | G26: 336 | H26: Mahesh sir wanted more clarity on Development for Heritage structures. Also plot size small | I26: Interested (P3) | J26: Landowner is actively looking for a partner
A27: Sumer Nagar | B27: Interested | D27: =VLOOKUP(A27,'Opps combined list'!$C$4:$E$42,2,FALSE) -> Borivali | E27: Redevelopment | F27: 12662 | G27: 1330 | H27: Shared with the group, they are evaluating | I27: Interested | J27: Society is actively looking to appoint Anex as their PMC
A28: Khajuria Nagar | B28: Interested - Get offer | C28: Send Feasibility for Offer | D28: Kandivali West | E28: Redevelopment | F28: 11895.33 | G28: 1200 | H28: Location Mentioned to Mahesh as slow cooking when we meet him, he was interested Prima facie | I28: Interested | J28: Society is actively looking for developers, open to one on one dealing
A29: Lokhandwala | D29: Versova | E29: Society Redevelopment | F29: - | G29: - | H29: Part of our initial discussions, the group has shown interest | I29: Slowing cooking | J29: Society is actively looking to appoint a PMC
A30: Nityanand Baug | D30: Chembr | E30: JV/JD | F30: 15348 | G30: 1650 | H30: Mahesh sir was not very Keen due to its history | I30: Dropped | J30: Society is actively looking to appoint a PMC
A31: Rajendra Park | B31: Dropped | D31: Goregoan West | E31: JV/JD | F31: 6777.82 | G31: 780 | H31: Mahesh sir was not very Keen due to its topline being small | I31: Dropped | J31: Existing developer is actively looking for a new partner
A32: Shivam Complex | B32: Dropped | D32: Vashi | E32: JV/JD | F32: 3493.5
A33: Dharavi SRA | B33: Dropped | D33: Dharavi | E33: JV/JD | F33: 5107
A34: SWAN | B34: Interested | D34: Sewri | E34: Outright | F34: 2521
A35: GTB | B35: Amit ji to discuss with SR | C35: Share IM | D35: GTB nagar | E35: JV/JD | F35: 20681.32
A36: Mulund - Transcon | B36: Dropped | D36: Mulund West | E36: JV/JD | F36: 80000
A37: Girgaum | B37: Interested | C37: Share IM | D37: Girgaon | E37: JV/JD | F37: 4605.38
A38: Diwan | B38: Dropped | D38: Marol | E38: Outright | F38: 8743
A39: Shedung | B39: Dropped | D39: Panvel | E39: Outright | F39: =18*4046 -> 72828
A40: Tolaram | B40: Interested | C40: Share IM | D40: Chembur | E40: Redevelopment | F40: 18618
A41: MTNL - 1 acre | B41: Interested | C41: Share IM | D41: Malad west | E41: Outright | F41: 4000
A42: Wise City | B42: Interested | C42: Prep | D42: Panvel | E42: Outright | F42: X
...

Sheet < 1,000 Sq.m. 
B4: Property | C4: Location | D4: Rescource | E4: Status | F4: SPOC / Agent | G4: Type | H4: Location | I4: Plot Size (sq.m.) | J4: FSI Potential | K4: Regulation Proposed | L4: Outright Price (INR)
A5: 1 | B5: Shishir | C5: Juhu | D5: Vru | E5: To be figured | F5: Duke | G5: Outright | H5: Maps | I5: 537 | J5: 5.4 | K5: 33(20B)
A6: 2 | B6: VIP | C6: Vile Parle East | D6: Vineet | E6: Cold | G6: Outright | H6: Maps | I6: 909.2 | J6: 3.04 | K6: 30(A) + 20(B) | L6: 27 Cr.
A7: 3 | B7: Plot next to Morumal Mansion CHSL | C7: Khar West | D7: SP | E7: Cold | F7: Dinesh | G7: Outright | H7: Maps | I7: 915 | J7: 5.4
A8: 4 | B8: Vijay Bharat | C8: andheri west | D8: SP | E8: To be revived | F8: Sachinji Solanki | G8: Outright | H8: Maps | I8: 1024 | J8: 5.4 | K8: 30(A)+20(B)
A9: 5 | B9: NS Juhu | C9: Juhu | F9: Hardik | G9: Outright | H9: Maps | I9: 829 | K9: FF not prepared | L9: 110 Cr.
A10: 6 | B10: Gitanjali CHS | C10: Santacruz East | E10: FF pending | F10: Pritesh Desai | G10: Outright | H10: Maps | I10: 1063 | K10: FF not prepared | L10: 50 Cr.
A11: 7 | B11: Sherly | C11: Bandra West | E11: FF pending | F11: Varun | G11: Outright | H11: Maps | I11: 412 | K11: FF not prepared | L11: 30 Cr.
A12: 8 | B12: Malti Mahal | G12: Outright | H12: Maps | I12: 568 | K12: FF not prepared | L12: 40 Cr.
A13: 9 | B13: Kothari Niwas | G13: Outright | H13: Maps | I13: 1711
A14: 10 | B14: Moray House | G14: Outright | H14: Maps | I14: 835 | L14: 75 Cr.
A15: 11 | B15: Redstone | G15: Outright | H15: Maps | I15: 814 | L15: 95 Cr.

Sheet Data Dump
B4: Propetry | C4: Location | D4: Handover | E4: Rescource | G4: Status | H4: SPOC / Agent | I4: Type 3 | J4: Location | K4: Plot size (sq.m.) | L4: FSI Potential | M4: Regulation Proposed | N4: Development Potential (sq.m.) | O4: Rehab Area (sq.m.) | P4: Sale Area (sq.m.) | Q4: Sale Rate Considered (psf) | R4: Initial Investment | S4: Profit | T4: Topline (in Crores) | U4: Next Step | V4: Latest update (Top to bottom) | W4: Click Up | X4: Excel
A5: 1 | B5: New Hindustan CHS | C5: Bandra W | G5: Dropped | H5: Sameer Sata | I5: Redevelopment | R5: =INDEX('Opps combined list'!$1:$1048576,MATCH('Data Dump'!$B48,'Opps combined list'!$C:$C,0),MATCH('Data Dump'!R$4,'Opps combined list'!$4:$4,0)) -> #N/A | S5: =INDEX('Opps combined list'!$1:$1048576,MATCH('Data Dump'!$B48,'Opps combined list'!$C:$C,0),MATCH('Data Dump'!S$4,'Opps combined list'!$4:$4,0)) -> #N/A | U5: Follow up | V5: Meeting done with Kishore Gala at Circuit City, to understand next steps / PMC appointment
A6: 2 | B6: Northern India CHSL | C6: Wadala | G6: Dropped | H6: Parimal Parekh | I6: Redevelopment | R6: =INDEX('Opps combined list'!$1:$1048576,MATCH('Data Dump'!$B123,'Opps combined list'!$C:$C,0),MATCH('Data Dump'!R$4,'Opps combined list'!$4:$4,0)) -> #N/A | S6: =INDEX('Opps combined list'!$1:$1048576,MATCH('Data Dump'!$B123,'Opps combined list'!$C:$C,0),MATCH('Data Dump'!S$4,'Opps combined list'!$4:$4,0)) -> #N/A | U6: Slow cooking | V6: -Meeting done, legal procedure being explained -To meet society and understand next steps prepare IM and Feasibility. Meeting scheduled for 13/10 @10:30 Am - Presentation to be prepared (Legal Note + Individual vs Cluster Pros & Cons)
A7: 3 | B7: Uttrayan CHS | C7: Andheri E | G7: Dropped | H7: AOS | I7: Redevelopment | R7: =INDEX('Opps combined list'!$1:$1048576,MATCH('Data Dump'!$B141,'Opps combined list'!$C:$C,0),MATCH('Data Dump'!R$4,'Opps combined list'!$4:$4,0)) -> #N/A | S7: =INDEX('Opps combined list'!$1:$1048576,MATCH('Data Dump'!$B141,'Opps combined list'!$C:$C,0),MATCH('Data Dump'!S$4,'Opps combined list'!$4:$4,0)) -> #N/A | U7: wait | V7: EOI sent - With society for consideration
A8: 4 | B8: Virwani CHSL | C8: Goregaon E | G8: Dropped | H8: AG | I8: Redevelopment | R8: =INDEX('Opps combined list'!$1:$1048576,MATCH('Data Dump'!#REF!,'Opps combined list'!$C:$C,0),MATCH('Data Dump'!R$4,'Opps combined list'!$4:$4,0)) -> #REF! | S8: =INDEX('Opps combined list'!$1:$1048576,MATCH('Data Dump'!#REF!,'Opps combined list'!$C:$C,0),MATCH('Data Dump'!S$4,'Opps combined list'!$4:$4,0)) -> #REF! | V8: -On Hold from Virvani's side -Sunteck has submitted an offer, to follow up with PMC. Sunteck revised offer pending
A9: 5 | B9: Gokul Regency one | C9: 0 | G9: Dropped | H9: 0 | I9: Redevelopment | V9: 0
A10: 6 | B10: Khandke Cluster | C10: Dadar W | G10: Dropped | H10: Mahendra Kasture | I10: Redevelopment | V10: Awaiting technical feasibility from the architect, MK to provide
A11: 7 | B11: Kitan apartments | C11: Matunga East | G11: Dropped | H11: BL Pandey | I11: Redevelopment | V11: 0
A12: 8 | B12: Land Breeze, Pali hill | C12: Bandra | G12: Dropped | H12: Prem/Sachin | I12: Redevelopment | V12: -Meet with Society. They want to get rid of current PMC
A13: 9 | B13: Lloyds Society | C13: Prabhadevi | G13: Dropped | H13: VKG | I13: Redevelopment | V13: Not lucrative - No action to be taken for VKG
A14: 10 | B14: Mangal Orchid | C14: Versova | G14: Dropped | H14: AOS | I14: Redevelopment | V14: Kuwadekar appointed
A15: 11 | B15: Neelkanth | C15: Matunga West | G15: Dropped | H15: Sachin Agrawal | I15: Redevelopment | U15: Follow up with Sachin
A16: 12 | B16: One Universe | C16: Oshiwara | G16: Dropped | H16: Ashok Kothari | I16: Redevelopment | K16: 0 | V16: - not feasibile -Study feasibility and understand development potential for further action. AG to get back on 08/10 | W16: Updated | X16: Updated
A17: 13 | B17: Orbit Ventures | C17: Lower Parel | G17: Dropped | H17: Vinita CBRE | I17: Redevelopment | K17: 0 | V17: To understand next steps
A18: 14 | B18: Parijat (Tender) | C18: 0 | G18: Dropped | H18: 0 | I18: Redevelopment | K18: 0 | V18: 0
A19: 15 | B19: Poonam Nagar MHADA | C19: Jogeshwari East | G19: Dropped | H19: 0 | I19: Redevelopment | K19: 0 | V19: -Dropped, not feasibile
A20: 16 | B20: Prathamesh CHS | C20: Andheri W | G20: Dropped | H20: Mr. Arvind Pahwa | I20: Redevelopment | K20: 0 | V20: - 5-6 buildings - background check then make inroads through SPOC
A21: 17 | B21: Raji Commercial Complex | C21: 0 | G21: Dropped | H21: 0 | I21: Redevelopment | K21: 0 | V21: 0
A22: 18 | B22: Sadguru | C22: Ghatkopar | G22: Dropped | H22: Agrawal | I22: Redevelopment | K22: 0 | V22: 0
A23: 19 | B23: Sai Ashish | C23: Mulund W | G23: Dropped | H23: Ashok Borana | I23: Redevelopment | K23: 0 | V23: Update to be taken for PMC Apppointment
A24: 20 | B24: Sandom Chawl | C24: Vile Parle | G24: Dropped | H24: Mahendra Kasture | I24: Redevelopment | K24: 0 | V24: - Land owner wants 60cr -JV Proposal - Queries with CTS, Development - Share with Veena,VKG, Vineet's uncle only IM (challenges (Metro Influence))
A25: 21 | B25: Shahid Bhagatsingh Nagar | C25: Bandra East | G25: Dropped | H25: 0 | I25: Redevelopment | K25: 0 | V25: -Update from Makwana needed
A26: 22 | B26: Shivdham | C26: Chembur | G26: Dropped | H26: Ashok Borana | I26: Redevelopment | K26: 0 | V26: Understand the status of appointing us as PMC.
A27: 23 | B27: Sholay CHS | C27: Andheri W | G27: Dropped | H27: Amit Wadhwani | I27: Redevelopment | K27: 0 | V27: -Vrushabh spoke, drop email -PMA, we have inroads, awaiting response
A28: 24 | B28: Shree Highland Park | C28: Kandivali | G28: Dropped | H28: Pradeep vasat (9819058565) | I28: Redevelopment | K28: 0 | V28: -Need to get data
A29: 25 | B29: Siddhivinayak CHS | C29: Kandivali W | G29: Dropped | H29: Agrawals | I29: Redevelopment | K29: 0 | V29: Feasibility to be prepared and shared with Mustakeen.
A30: 26 | B30: St. Pius | C30: Mulund W | G30: Dropped | H30: Ashok Borana | I30: Redevelopment | K30: 0 | V30: -PMC tender will come out -Site visit to be done in the week commencing 07/10
A31: 27 | B31: Suraiya Apartments | C31: Worli | G31: Dropped | H31: Colliers | I31: Redevelopment | K31: 0 | V31: FF Ready - meet with office bearers to understand next steps
A32: 28 | B32: Manju | C32: Sher-e-Punjab | G32: Dropped | H32: Inder | I32: Redevelopment | K32: 0 | L32: =INDEX('Opps combined list'!$1:$1048576,MATCH('Data Dump'!$B40,'Opps combined list'!$C:$C,0),MATCH('Data Dump'!L$4,'Opps combined list'!$4:$4,0)) -> #N/A | R32: =INDEX('Opps combined list'!$1:$1048576,MATCH('Data Dump'!$B40,'Opps combined list'!$C:$C,0),MATCH('Data Dump'!R$4,'Opps combined list'!$4:$4,0)) -> #N/A | S32: =INDEX('Opps combined list'!$1:$1048576,MATCH('Data Dump'!$B40,'Opps combined list'!$C:$C,0),MATCH('Data Dump'!S$4,'Opps combined list'!$4:$4,0)) -> #N/A | V32: Evaluated, not feasibile. Inder ji likes
A33: 29 | B33: Twinkle Star | C33: 0 | G33: Dropped | H33: 0 | I33: Redevelopment | K33: 0 | V33: 0
A34: 30 | B34: Unnat Nagar | C34: 0 | G34: Dropped | H34: BL Pandey | I34: Redevelopment | K34: 0 | V34: 0
A35: 31 | B35: Vaibhav Palace | C35: 0 | G35: Dropped | H35: 0 | I35: Redevelopment | K35: 0 | V35: -Dropped, not feasibile
A36: 32 | B36: Vitta Sanchay CHSL (Self Redevelopment) | C36: Chembur | E36: Shali | G36: Dropped | H36: Harshal Choudhary | I36: Redevelopment | K36: 0 | V36: Not Shortlisted
A37: 33 | B37: Kishori Court | C37: Worli Sea Face | G37: Dropped | H37: BL Pandey | I37: Outright | K37: 0 | V37: Dead
A38: 34 | B38: Rukiya Manzil Volkart House | C38: Warden Road | G38: Dropped | H38: BL Pandey | I38: Outright | K38: 0 | V38: Applied for PMC, survey to be conducted, feasibility prepared. (Dropped)
A39: 35 | B39: Devki Niwas CHSL | C39: Sion | E39: Sagar | G39: Dropped | H39: Pranay Kamat | I39: Redevelopment | K39: 503.35 | V39: Not Feasible
A40: 36 | B40: Neel Sagar | C40: Prabhadevi | G40: Slow Cooking | H40: Rajendra | K40: 516 | L40: 4.05 | M40: 33(11) | N40: 2089 | O40: 1057 | P40: 1032 | Q40: 67500 | R40: 7 | S40: 14 | T40: 69 | W40: Updated | X40: Updated
A41: 37 | B41: Dominic Condiminum | C41: Bandra | G41: Dropped | H41: 0 | I41: Redevelopment | K41: 516.7 | L41: 4.05 | M41: 33(7B )+ 33(12B) | N41: 2092.64 | O41: - | P41: 2093 | Q41: 60000 | T41: 126 | U41: Hunt | V41: Plot evaluated | W41: Updated | X41: Updated
A42: 38 | B42: Shishir | C42: Juhu | E42: Vru | G42: Dropped | H42: 0 | I42: Redevelopment | J42: Map | K42: 537 | L42: 5.4 | M42: 33(20B) | N42: 2900 | O42: 1316 | P42: 1462 | Q42: 85000 | R42: 17 | S42: 24 | T42: 123 | U42: Follow up | V42: Fitment requested from Foram
A43: 39 | B43: Gita | C43: Sion | G43: Dropped | H43: 0 | I43: Redevelopment | K43: 590 | V43: -Not feasible
...

Sheet List for Casa
C3: List of Opportunities
C6: Name of Society | D6: Deal Type | E6: Location | F6: Location Pin | G6: Plot size (sq.m.) | H6: Regulation Proposed | I6: Topline (in Crores) | K6: Comment
C7: Vinay Industrial Estate | D7: Redevelopment | E7: Malad West | F7: Maps | G7: 4688.2 | H7: 33(19) | I7: 753 | K7: Commercial not interested
C8: Singh Estate | D8: Outright + Redevelopment | E8: Dadar East | F8: Maps | G8: 7562.71 | H8: 33(9) | I8: 1160 | K8: Site Visit Proposed
C9: CSP & Chakreshwari CHSL | D9: Redevelopment | E9: Mulund West | F9: Maps | G9: 10429 | H9: 33(9) | I9: 935 | K9: Not Interested, no margins, 32000 too high
C10: Deepak Jyoti Parel | D10: Redevelopment | E10: Parel | F10: Maps | G10: 12080.7 | H10: 33(9) | I10: 1643 | K10: Risk with the Title with the Trust
C11: Diwan Land | D11: Outright | E11: Marol | F11: Maps | G11: 8743 | H11: 33(19) | I11: 1324 | K11: JV/JD preference
C12: Ruby Apartments | D12: Outright + Redevelopment | E12: Juhu | F12: Maps | G12: 1765.5 | H12: 33(7B)+33(20B) | I12: 416 | K12: Interested - FF - Legal Query
C13: Powai | D13: Outright + Redevelopment | E13: Powai | F13: Maps | G13: 33364.8 | H13: 33(11) | I13: 5700 | K13: Avoid Mangesh
C14: LIC Colony | D14: Redevelopment | E14: Mulund West | F14: Maps | G14: 15804.7 | H14: 33(9) | I14: 1180 | K14: Interested - FF - Sale Rate - 25K - Conveyance
C15: Dakshin Pali | D15: Redevelopment | E15: Bandra West | F15: Maps | G15: 3854.6 | H15: 33(7B)+33(12B) | I15: 834 | K15: Interested - FF - Legal Query
C16: Manish Nagar | D16: Redevelopment | E16: Andheri W | F16: Maps | G16: 40000 | H16: 33(9)
C17: Wise City | D17: Outright | E17: Panvel | F17: Maps | K17: Corporate Sturture Query
C18: Adarsh Nagar | D18: Redevelopment | E18: Worli | F18: Maps
C19: Goregaon Commercial | D19: JV/JD | E19: Goregaon | F19: Maps | G19: 15000 | H19: 33(10)
C20: Shedung land

Sheet Manish and Juhu
F3: Manish Nagar
F4: Developer | G4: Status
F5: Birla
F6: Sobha
F7: Raymond
F8: My Home
F9: Casagrande
F10: Sattva
F11: Embassy
F12: Ramky
F13: Piramal
F14: Purvankara
F15: Kalpataru
F16: Wadhwa
... F20: HOH

Sheet Neelam, Nitul, Ajay, Harshad
B2: Property | C2: Location | D2: Maps | E2: Plot Area | F2: Sourcing Partner
B3: BPL | C3: Matunga | D3: Maps | E3: 2584 | F3: Ajay Vora
B4: Karanjade Land | C4: JNPT, Navi Mumbai | F4: Ajay Vora
B5: CSP & Chakreshwari CHSL | C5: Mulund West | D5: Maps | E5: 10429 | F5: Dipen
B6: Punjab Society | C6: Santacruz West | E6: 4017 | F6: Dipen
B7: Shivam Complex Vashi | C7: Vashi | D7: Maps | E7: 3493 | F7: Harshad Dalvi
B8: Noorani Building | C8: Mahim West | D8: Maps | E8: 1604 | F8: Harshad Dalvi
B9: Roshan Apartments | C9: Borivali East | E9: - | F9: Harshad Dalvi
B10: Koregaon Park Redevelopment | C10: Pune | E10: ~3.5 Acre | F10: Harshad Dalvi
B11: AB Chawl | C11: Lower Parel | D11: Maps | E11: 1994 | F11: Neelam Sanghvi
B12: Napean House | C12: Malabar Hill | D12: Maps | E12: 2006 | F12: Neelam Sanghvi
B13: Walkeshwar Cluster | C13: Malabar Hills | D13: Maps | E13: - | F13: Neelam Sanghvi
B14: Worli Church Property | C14: Worli | D14: Maps | E14: 2648 | F14: Neelam Sanghvi
B15: Navyug Nagar | C15: Tardeo | D15: Maps | E15: 4942 | F15: Neelam Sanghvi
B16: Empire Guide | C16: Malabar hills | D16: Maps | E16: 4006 | F16: Neelam Sanghvi
B17: Giriraj | C17: Malabar hills | E17: - | F17: Neelam Sanghvi
B18: AAI Property | C18: Andheri East | E18: ~5.5 Acre | F18: Nitul
B19: Bapsola / Noor E Rehmat | C19: Bandra West | D19: Maps | E19: 1865 | F19: Nitul
B20: Anand Nagar | C20: Dahisar | E20: - | F20: Nitul

Sheet PMC-PMA 
B2: Name of Society | C2: Location | D2: Location Pin | E2: Plot size (sq.m.) | F2: Regulation Proposed | G2: Engagement
A3: 5 | B3: Triveni CHSL | C3: Mulund West | D3: Maps | F3: 33(9) | G3: PMC
A4: 1 | B4: Prahlad CHSL | C4: Santacruz West | D4: Maps | E4: 2418.71 | F4: 33(11) | G4: PMC
A5: 1 | B5: Ayodhya CHSL | C5: Lower Parel | D5: Maps | E5: 4278.91 | F5: 33(7) + 33(9) | G5: PMC
A6: 1 | B6: Dudhsagar CHSL | C6: Goregaon East | D6: Maps | E6: 19976.72 | F6: 33(9) | G6: PMA
A7: 1 | B7: Mahindra CHSL | C7: Malad East | D7: Maps | E7: 58367 | F7: 33(9) | G7: PMA
A8: 1 | B8: Khajuria CHSL | C8: Kandivali West | D8: Maps | E8: 11895.33 | F8: 30(A) + 33(20B) + 17 | G8: PMA
A9: 1 | B9: New Jal Darshan | C9: Bandra West | D9: Maps | E9: 2053.2 | F9: 33(11) | G9: PMC
A10: 1 | B10: Rajiv | C10: Bandra East | D10: Maps | E10: 1787 | F10: 33(7B) +20(B) | G10: PMC
A11: 1 | B11: Divya Jyot | C11: Andheri East | D11: Maps | E11: 1212 | F11: 33(10) | G11: PMC
A12: 3+1 | B12: Manish Nagar | C12: Andheri West | D12: Maps | E12: 7620 | F12: 33(7B) +20(B) | G12: PMC
A13: 4 | B13: Lokhandwala Cluster | G13: PMC
A14: 1 | B14: Samarth Nagar | G14: PMA
A15: 1 | B15: Gloma | G15: PMC

Sheet Opps combined list
C1: List of Opportunities
C4: Name of Society | D4: Location | E4: Deal Type | F4: Location Pin | G4: Plot size (sq.m.) | H4: FSI Potential | I4: Regulation Proposed | J4: Development Potential (sq.m.) | K4: Rehab Area (sq.m.) | L4: Sale Area (sq.m.) | M4: Sale Rate Considered (psf) | N4: Initial Investment | O4: Profit | P4: Topline (in Crores)
C5: 2 Acre Kalina | D5: Santacruz East | E5: Outright | F5: Maps | G5: 9991 | H5: 6.75 | I5: 33(19) | J5: 60695.325 | K5: 0 | L5: 60695.325 | M5: 50000 | P5: 300
C6: Aangan & Maryland | D6: Sion East | E6: Society Redevelopment | F6: Map | G6: 3508 | H6: 5.4 | I6: 33(11) | J6: 18945 | K6: 7314 | L6: 11599 | M6: 35000 | P6: 580
C7: Ambedkar Nagar CHSL | D7: Worli | E7: Society Redevelopment | F7: Maps | G7: 9311 | H7: 5.4 | I7: 33(5) | J7: 43212 | K7: 20196 | L7: 23015 | M7: 65000 | N7: 90 | O7: 235 | P7: 1481
C8: ARC - Daya | D8: Goregaon East | E8: Outright | F8: Maps | G8: 6032 | H8: 2.97 | I8: 30(A) + 17(1) | J8: 22846 | K8: 2227 | L8: 20619 | M8: 30000 | N8: 83 | O8: 170 | P8: 612
C9: Ashokraj Topiwala Washington | D9: Goregaon West | E9: Society Redevelopment | F9: Maps | G9: 6737 | H9: 5.4 | I9: 33(9) | J9: 46317 | K9: 19869 | L9: 24363 | M9: 33315 | N9: 84 | O9: 171 | P9: 676
C10: Ayodhya CHSL | D10: Lower Parel | E10: Society Redevelopment | F10: Maps | G10: 4278.91 | H10: 7.02 | I10: 33(7) + 33(9) | J10: =30028 -> 30028 | K10: 13841 | L10: =162021/10.764 -> 15052.118 | M10: 42500 | P10: 681 | Q10: =SUM(K10+L10) -> 28893.118 | R10: =J10-Q10 -> 1134.8818
C11: Bara Chawl + Topowan | D11: Lower Parel | E11: SRA | F11: Maps | G11: 4215.76 | H11: 14.04 | I11: 33(9) | J11: 59205 | K11: 27456 | L11: 31703 | M11: 42000 | P11: 1459
C12: Bezzola Complex | D12: Chembur | E12: Society Redevelopment | F12: Maps | G12: 11502.2 | H12: 6.75 | I12: 33(19) | J12: 77639.85 | K12: 16875.72 | L12: 60730.1 | M12: 32500 | P12: 1922
C13: Borla | D13: Chembur | E13: Society Redevelopment | F13: Maps | G13: 13890.2 | H13: 5.4 | I13: 33(9) | J13: 75007 | K13: 22486 | L13: 52521 | M13: 42000 | P13: 2400
C14: Brindaban Dham | D14: Juhu | E14: Society Redevelopment | F14: Maps | G14: 887 | H14: 5.4 | I14: 33(7B)+33(20B) | J14: 4791 | K14: 1129 | L14: 2162 | M14: 60000 | P14: 156 | Q14: =SUM(K14+L14) -> 3291 | R14: =J14-Q14 -> 1500
C15: Dominic Condiminum | D15: Bandra West | E15: Outright | F15: Map | G15: 516.7 | H15: 4.05 | I15: 33(7B )+ 33(12B) | J15: 2092.64 | K15: - | L15: 2093 | M15: 60000 | P15: 126
C16: Gandhi Market | D16: Sion | E16: Society Redevelopment | F16: Maps | G16: 5894.7 | H16: 6.26 | I16: 33(9) | J16: 34209 | K16: 16687 | L16: 17521 | M16: 45000 | P16: 780
C17: Goshala road Cluster | D17: Mulund West | E17: Society Redevelopment | F17: Map | G17: 3394.3 | H17: 5.4 | I17: 33(7B) + 33(20B) | J17: 18182.502 | K17: 6091.585 | L17: 10919.383 | M17: 23000 | P17: 250 | Q17: =SUM(K17+L17) -> 17010.968 | R17: =J17-Q17 -> 1171.5336
C18: Harshad CHSL | D18: Sion East | E18: Society Redevelopment | F18: Maps | G18: 2989 | H18: 5.4 | I18: 30(7B) + 20(B) | J18: 16141 | K18: 4044 | L18: 12097 | M18: 28000 | N18: 25 | O18: 79 | P18: 340
C19: Jasmine & Moonira lodge | D19: Colaba Causeway | E19: JV/JD | F19: Maps | G19: 1270.91 | H19: 5.4 | I19: 33(7) + 33(12B) | J19: 6533 | K19: 2421 | L19: 4112 | M19: 110000 | N19: 110 | O19: 110 | P19: 336
C20: JVLR Cluster | D20: Jogeshwari East | E20: Society Redevelopment | F20: Maps | G20: 7276 | H20: 7.1 | I20: 33(9) | J20: 51909 | K20: 25624 | L20: 26588 | M20: 31000 | P20: 1021 | Q20: =SUM(K20+L20) -> 52212 | R20: =J20-Q20 -> -303
C21: Khajuria Nagar | D21: Kandivali West | E21: Society Redevelopment | F21: Maps | G21: 11895.33 | H21: 5.4 | I21: 30(A) + 33(20B) + 17 | J21: 58298.994 | K21: 11567.197 | L21: 45528.808 | M21: 27000 | N21: 60 | O21: 250 | P21: 1218 | Q21: =SUM(K21+L21) -> 57096.006 | R21: =J21-Q21 -> 1202.9885
C22: Labh Niwas & Subh Niwas CHSL | D22: Ghatkopar East | E22: JV/JD | F22: Maps | G22: =1899.5 -> 1899.5 | H22: 4.05 | I22: 33(19) | J22: 7693 | K22: 2742 | L22: 4951 | M22: 40000 | P22: 199
C23: Laxminarayan & Devlok | D23: Santacruz West | E23: Society Redevelopment
C24: Lokhandwala Cluster | D24: Andheri West | E24: Society Redevelopment | F24: Maps | G24: 16932 | H24: 6.8 | I24: 33(9) | J24: 114595 | K24: 52197 | L24: 60026 | M24: 45000 | P24: 2722 | Q24: =SUM(K24+L24) -> 112223 | R24: =J24-Q24 -> 2372
C25: Mahindra Nagar | D25: Malad East | E25: Society Redevelopment | F25: Maps | G25: 58367 | H25: 5.4 | I25: 33(9) | J25: 179143 | K25: 53217 | L25: 93254 | M25: 30000 | P25: 3700 | Q25: =SUM(K25+L25) -> 146471 | R25: =J25-Q25 -> 32672
C26: Maker Mahal | D26: Bandra West | E26: Outright | F26: Maps | G26: 2025.9 | H26: 5.4 | I26: 30(A) + 20(B) | J26: 9154.62 | K26: 0 | L26: 9154.62 | M26: 80000 | N26: 173 | O26: 186 | P26: 800
C27: Manish Nagar | D27: Andheri West | E27: Society Redevelopment | F27: Maps | G27: 10217 | H27: 5.4 | I27: 33(9) | J27: 55172 | K27: 16161 | L27: 36671 | M27: 35000 | P27: 1270 | Q27: =SUM(K27+L27) -> 52832 | R27: =J27-Q27 -> 2340
C28: Mon Desire | D28: Bandra west | E28: Society Redevelopment
C29: Nalanda CHSL | D29: Malad West | E29: Society Redevelopment | F29: Maps | G29: 6680 | I29: 33(9) | J29: 34605 | K29: 12686.56 | Q29: =SUM(K29+L29) -> 12686.56 | R29: =J29-Q29 -> 21918.44
C30: Narayana Guru CHS | D30: Chembur | E30: Society Redevelopment | F30: Maps | G30: 9486 | H30: 4.94 | I30: 33(9) | J30: 46878 | K30: 13449 | L30: 25812 | M30: 24000 | P30: 731 | Q30: =SUM(K30+L30) -> 39261 | R30: =J30-Q30 -> 7617
C31: New Jal Darshan | D31: Bandra West | E31: Society Redevelopment | F31: Maps | G31: 2053.2 | H31: 4.05 | I31: 33(11) | J31: 8315.46 | K31: 4113.5909 | L31: 3670.8419 | M31: 80000 | P31: 290 | Q31: =SUM(K31+L31) -> 7784.4328 | R31: =J31-Q31 -> 531.02719
C32: Nityanand Bagh | D32: Chembur | E32: Society Redevelopment | F32: Maps | G32: 15348 | H32: 5.4 | I32: 33(9) | J32: 77973 | K32: 25838 | L32: =J32-K32 -> 52135 | M32: 30000 | P32: 1650
C33: Prahlad CHSL | D33: Santacruz West | E33: Society Redevelopment | F33: Maps | G33: 2418.71 | H33: 5.4 | I33: 33(11) | J33: 12521 | K33: 4733 | L33: 7541 | M33: 65000 | N33: 79 | O33: 113 | P33: 513 | Q33: =SUM(K33+L33) -> 12274 | R33: =J33-Q33 -> 247
C34: Rajendra Park CHS | D34: Goregoan West | E34: Society Redevelopment | F34: Maps | G34: 6777.82 | H34: 5.4 | I34: 33(9) | J34: 32322.205 | K34: 8246.8985 | L34: 24075.307 | M34: 31500 | P34: 780
C35: Redstone | D35: Juhu | E35: JV/JD | F35: Maps | G35: 1392 | H35: 5.4 | I35: 30(A)+33(20B) | J35: 7517 | K35: - | L35: 7517 | M35: 65000 | N35: 120 | O35: 77 | P35: 386
C36: Sagar CHSL | D36: Mahim | E36: Society Redevelopment | F36: Maps | G36: 4229 | H36: 6.62 | I36: 33(5) | J36: 27371 | K36: 12415 | L36: 14956 | M36: 42000 | P36: 622
C37: Shree Niketan | D37: Santacruz West | E37: Society Redevelopment | F37: Maps | G37: 2416 | H37: 5.4 | I37: 33(11) | J37: 13046 | K37: 0 | L37: 13046 | M37: 75000 | P37: 1075
C38: Shree Ram | D38: Andheri West | E38: Society Redevelopment | F38: Maps | G38: 13882 | H38: 3.3 | I38: 33(7B) | J38: 42900 | K38: 14992 | L38: 27811 | M38: 38000 | N38: 112 | O38: 216 | P38: 1101 | Q38: =SUM(K38+L38) -> 42803 | R38: =J38-Q38 -> 97
C39: Snehadhara CHSL | D39: Santacruz West | E39: Society Redevelopment | F39: Maps | G39: 12955.6 | H39: 3 | I39: 33(11) | J39: 39352.635 | K39: 16036.395 | L39: 20232.12 | M39: 44000 | P39: 970 | Q39: =SUM(K39+L39) -> 36268.515 | R39: =J39-Q39 -> 3084.1196
C40: Sumer Nagar | D40: Borivali | E40: Society Redevelopment | F40: Maps | G40: 12662 | H40: 5.4 | I40: 33(9) | J40: 68375 | K40: 31810 | L40: 36569 | M40: 35000 | P40: 1330
C41: Tolaram | D41: Chembur | E41: Society Redevelopment | F41: Maps | G41: 18618 | H41: 5.4 | I41: 33(9) | J41: 89173 | K41: 18295 | L41: =J41-K41 -> 70878 | M41: 30000 | P41: 2000
C42: Woodstock CHSL | D42: Versova | E42: Society Redevelopment | F42: Maps | G42: 6653 | H42: 5.1 | I42: 33(9) | J42: 33941 | K42: 9893 | L42: 20824 | M42: 50000 | P42: 1120 | Q42: =SUM(K42+L42) -> 30717 | R42: =J42-Q42 -> 3224

Sheet Proposal Tracker
G1: x | H1: o | I1: ☑ | J1: S | K1: i
G2: Declined | H2: Sent | I2: EOI Rec. | J2: To be Sent | K2: interested
B4: Status | D4: PoC - 1 | E4: PoC - 2 | F4: Runwal - Sandeep | G4: Runwal - Subodh | H4: Sobha | I4: L&T | J4: Mahindra | K4: HOH | L4: Kolte Patil | M4: Sattva | N4: Ramky | O4: Crest | P4: Prescon | Q4: NCC | R4: Sunteck | S4: VKG | T4: Kabra | U4: Raymond | V4: SKS Anchor Point | W4: Moongipa | X4: Kanakia | Y4: Hines | Z4: H.rishabhraj | AA4: Aditya Birla | AB4: Veena | AC4: DGS | AD4: K Raheja | AE4: Matrix | AF4: Kohinoor | AG4: Greenscape | AH4: Sonal | AI4: Q group | AJ4: Raheja Homes | AK4: Silver | AL4: Bluekey realty | AM4: Arkade | AN4: Lloyds | AO4: Sugee | AP4: Aditya Raj | AQ4: Pushpa Raj | AR4: Mass Group | AS4: Sumukha | AT4: Arth | AU4: Sai | AV4: Om | AW4: Mohite | AX4: Tater World | AY4: AVSN | AZ4: B-right | BA4: Puri Creators | BB4: Paradigm | BC4: Maniar | BD4: Agami | BE4: K Nagpal | BF4: Piramal | BG4: Kalpataru | BH4: Sheth | BI4: Tribeca | BJ4: Supreme | BK4: Woodstock | BL4: Akshay Group | BM4: JSW | BN4: Shree Malli Realty | BO4: Authum Infra
B5: 1 | C5: 17Acre Versova | D5: Shalibhadra | E5: Vineet | K5: S | M5: S
C6: Ambedkar Nagar, Worli | F6: x | G6: i | H6: S | I6: i | J6: o | K6: o | L6: i | M6: i | N6: ☑ | Q6: o | T6: o | AK6: o
C7: Aminia | N7: o | O7: o | AD7: o
C8: Anand Nagar Santacruz | N8: o | S8: o | W8: o
C9: Borla | H9: ☑ | I9: o | J9: o | K9: X | L9: X | M9: X | N9: ☑ | Q9: o
C10: Jasmine (JV/JD) | F10: x | G10: x | J10: o | K10: S | L10: S | M10: S | N10: o | P10: o
C11: Khajuria Nagar | F11: o | G11: o | I11: S | J11: S | K11: S | L11: S | N11: o
C12: Madhugiri | N12: o | AW12: o | AX12: o
C13: Moray House | O13: o
C14: Navyug - Forjett | G14: o | H14: o | N14: o | X14: o | AA14: o | AB14: o | AD14: o | AN14: o
C15: New Jal Darshan | G15: i | H15: S | I15: o | J15: S | K15: S | L15: S | M15: S
C16: Nityanand Baug | G16: x | H16: o | I16: o | J16: o | K16: S | L16: i | M16: X | N16: o | Q16: ☑ | R16: o | T16: o | U16: o | V16: o | X16: o | Z16: o | AB16: o | AI16: o | AM16: o
C17: Prahlad CHSL - Santacurz | H17: o | I17: o | K17: S | L17: S | M17: S | N17: o | Q17: o
C18: Rajendra Park & Nalanda Mall, Goregaon (West) | F18: i | G18: o | J18: X | L18: o | M18: x | Q18: o | S18: o | T18: o | V18: o | X18: o | Z18: o | AB18: o | AH18: o | AI18: o | AZ18: o
C19: Sagar, Mahim | J19: S | P19: o | Q19: o | T19: o | W19: o | X19: o | AK19: o | AL19: o
C20: Shree Ram CHSL, Andheri (West) | I20: i | J20: S | K20: ? | L20: ☑ | M20: i | N20: ☑ | Q20: ☑
C21: Snehdhara | L21: o | N21: ☑ | Q21: ☑
C22: Sumer Nagar | F22: i | G22: o | H22: o | I22: o | J22: o | K22: X | L22: o | M22: i | N22: ☑ | Q22: ☑ | S22: o | U22: o | Z22: o | AA22: o | AB22: o | AC22: o | AD22: o
C23: Tolaram | G23: i | H23: o | I23: o | J23: o | L23: o | M23: X | N23: ☑ | Q23: ☑ | U23: o | AA23: o | AM23: o
C24: Harshad CHSL | L24: o | M24: i | N24: o | P24: o | T24: o | W24: o | AF24: o | AN24: x | AP24: o | AQ24: o | AS24: o
C25: Redstone, Juhu | F25: x | G25: x | K25: x | L25: i | M25: i | N25: o | O25: o | P25: ☑ | Q25: o | V25: i | X25: o | AD25: o | AO25: o | AS25: o | BD25: o | BE25: o
C26: ARC - Goregaon | N26: o | Q26: x | T26: o | Z26: o | AB26: o | AC26: o | BC26: o | BD26: o
C27: Labh Niwas & Subh Niwas CHSL
C28: Laxminarayan & Devlok | AO28: o
C29: Bezzola, Chembur | N29: o | P29: X | AG29: o
C30: Nalanda Malad | T30: o | V30: o
C31: Mahindra Nagar | I31: o | K31: S | M31: S
C32: Manish Nagar
C33: Shree Ganesh Krupa | AV33: o | AY33: o | BA33: o
C34: Thane VKG - JV/JD | H34: S | I34: S | J34: S | K34: S
C35: Triveni - Mulund | J35: S | L35: S | X35: o | AE35: o | AF35: o | AJ35: o | AK35: o | AR35: o | AS35: o | AU35: o | AZ35: o
C36: VKG, Kandivali | N36: o
C37: Brindaban Dham
C38: Bara Chawl | P38: o | X38: o | AK38: o | AT38: o
C39: BKC Kapadia - VKG - JV/JD | H39: S | I39: S | J39: S | M39: S
C40: Bara Chawl + Topowan | P40: o | AA40: o | AT40: X
C41: Himalaya
...

Sheet List of Active Developers 
B1: List of Developers | C1: Email ID
A2: 1 | B2: Runwal - Sandeep
A3: 2 | B3: Runwal - Subodh
A4: 3 | B4: Sobha
A5: 4 | B5: L&T
A6: 5 | B6: Mahindra
A7: 6 | B7: HOH
A8: 7 | B8: Kolte Patil
A9: 8 | B9: Sattva
A10: 9 | B10: Ramky
A11: 10 | B11: Crest
A12: 11 | B12: Prescon
A13: 12 | B13: NCC
... A38: 37 | B38: NESCO
A39: 38
A40: 39
A41: 40
A42: 41

Sheet Sheet1
B2: Propetry | C2: Location | D2: Rescource | E2: Status | F2: SPOC / Agent | G2: Type 3 | H2: Location | I2: Plot size (sq.m.) | J2: FSI Potential | K2: Regulation Proposed
A3: =A2+1 -> 1 | B3: Borla | C3: Chembur | D3: Shali | E3: Active | F3: Ashok | G3: Redevelopment | H3: Maps | I3: 13890.2 | J3: 5.4 | K3: 33(9)
A4: =A3+1 -> 2 | B4: 2 Acre Kalina | C4: Bandra East | D4: SP | E4: Slow cooking | F4: Jejesh | G4: Outright | H4: Maps | I4: 9991 | J4: 6.75 | K4: 33(19)
A5: =A4+1 -> 3 | B5: Tolaram | C5: Chembur | D5: Shali/SP | E5: Hot | F5: Adinath | G5: Redevelopment | H5: Maps | I5: 18618 | J5: 4.79 | K5: 33(9)
A6: =A5+1 -> 4 | B6: Nityanand Bagh | C6: Chembur | D6: Shali/SSD | E6: Hot | F6: Mr. Thakur (Mahendra Kasture) | G6: Redevelopment | H6: Maps | I6: 15348 | J6: 5.4 | K6: 33(9)
A7: =A6+1 -> 5 | B7: Bezzola Complex | C7: Chembur | D7: SP | E7: Dropped | F7: Adinath | G7: Redevelopment | H7: Maps | I7: 11502.2 | J7: 6.75 | K7: 33(19)
A8: =A7+1 -> 6 | B8: Sumer Nagar | C8: Borivali West | D8: SP | E8: Active | F8: Chandrashekhar | G8: Redevelopment | H8: Maps | I8: 12662 | J8: 5.4 | K8: 33(9)
A9: =A8+1 -> 7 | B9: Ambedkar Nagar CHSL | C9: Worli | D9: Vineet | E9: Active | F9: Agrawals | G9: Redevelopment | H9: Maps | I9: 9311 | J9: 5.4 | K9: 33(5)
A10: =A9+1 -> 8 | B10: Manish Nagar | C10: Andheri W | D10: SP/Sagar | E10: Active | F10: Jayantilal Patel | G10: Redevelopment | H10: Maps | I10: 10217 | J10: 5.4 | K10: 33(9)
A11: =A10+1 -> 9 | B11: Khajuria Nagar | C11: Kandivali West | D11: Sahil | E11: Active | F11: Vijay Mundra | G11: Redevelopment | H11: Maps | I11: 11895.33 | J11: 4.34 | K11: 33(9)
A12: =A11+1 -> 10 | B12: Shree ram | C12: Andheri W | D12: SP | E12: Active | F12: AV Rajan | G12: Redevelopment | H12: Map | I12: 13882 | J12: 3.3 | K12: 33(7B)
A13: =A12+1 -> 11 | B13: Shree Niketan | C13: Santacruz W | D13: Shali | E13: Active | F13: Sameer Sata | G13: Redevelopment | H13: Maps | I13: 2416 | J13: 5.4 | K13: 33(11)
A14: =A13+1 -> 12 | B14: Woodstock CHSL | C14: Versova | D14: Vru | E14: Slow cooking | F14: - | G14: Redevelopment | H14: Maps | I14: 6653 | J14: 5.1 | K14: 33(9)
... A17: =A16+1 -> 15 | B17: Karnatak CHSL | C17: Matunga | D17: Vineet | E17: Active | F17: Ramesh | G17: Redevelopment | H17: Maps | I17: 5850 | J17: 5.4 | K17: 33(9)
A18: =A17+1 -> 16 | B18: LIC Colony | C18: Mulund West | D18: Sagar | E18: Hot | G18: Redevelopment | H18: Maps | I18: 10715 | J18: 4.7 | K18: 33(9)
A19: =A18+1 -> 17 | B19: Maker Mahal | C19: Bandra West | D19: SP | E19: Hot | G19: Outright | H19: ='[1]Reg. 33(11)'!F37 -> m | I19: 2025.9 | J19: 5.4 | K19: 30(A) + 20(B)
A20: =A19+1 -> 18 | B20: Rajendra Park CHS | C20: Goregaon West | D20: Vineet | E20: Active | F20: Sonali RERA | G20: Redevelopment | H20: Maps | I20: 6777.82 | J20: 5.4 | K20: 33(9)
A21: =A20+1 -> 19 | B21: Ayodhya CHSL | C21: Lower Parel | D21: Vineet | E21: Active | F21: Stanley & Sameer Kadri | G21: Redevelopment | H21: Maps | I21: 4278.91 | J21: 7.02 | K21: 33(9)
A22: =A21+1 -> 20 | B22: Nalanda CHSL | C22: Malad | D22: Sagar | E22: Active | G22: Redevelopment | H22: Maps | I22: 6680 | J22: 5.18 | K22: 33(9)
A23: =A22+1 -> 21 | B23: Dadar Avanti CHSL | C23: Dadar W | D23: Vineet | E23: Active | G23: Redevelopment | H23: Maps | I23: 4801 | J23: 5.4 | K23: 33(9)
A24: =A23+1 -> 22 | B24: Gandhi Market | C24: Sion | E24: Dropped | F24: BL Pandey | G24: Redevelopment | I24: 5894.7 | J24: 6.26 | K24: 33(9)
A25: =A24+1 -> 23 | B25: Himalaya | C25: Worli | D25: Vineet | E25: Active | F25: 0 | G25: Redevelopment | H25: Map | I25: 2661 | J25: 5.4 | K25: 33(20B)
A26: =A25+1 -> 24 | B26: Narayana Guru CHS | C26: Chembur | E26: Dropped | F26: Mr. Thakur (Mahendra Kasture) | G26: Redevelopment | H26: MAPS | I26: 9486 | J26: 4.94 | K26: 33(9)
A27: =A26+1 -> 25 | B27: Asia Chemical Works | C27: Andheri East | D27: Vineet | E27: Active | F27: Vinay | G27: Ouright | H27: Maps | I27: 3644 | J27: 4.05 | K27: 33(11)
A28: =A27+1 -> 26 | B28: Prahlad CHSL | C28: Santacruz | D28: Vineet | E28: Active | F28: Prem | G28: Redevelopment | H28: Maps | I28: 2418.71 | J28: 5.4 | K28: 33(11)
A29: =A28+1 -> 27 | B29: Jasmine & Moonira lodge | C29: Colaba Causeway | D29: Sagar | E29: Active | F29: Vijay Mundra & Naveen Parikh | G29: JV/JD | H29: Maps | I29: 1270.91 | J29: 5.4 | K29: 33(7) + 33(12B)
A30: =A29+1 -> 28 | B30: New Jal Darshan | C30: Bandra W | E30: Won | F30: Sachin Agrawal | G30: Redevelopment | H30: Maps | I30: 2053.2 | J30: 4.05 | K30: 33(11)
A31: =A30+1 -> 29 | B31: Aangan & Maryland | C31: Sion | D31: Vineet | E31: Slow cooking | F31: Sachin Agrawal | G31: Redevelopment | H31: Map | I31: 3508 | J31: 5.4 | K31: 33(11)
A32: =A31+1 -> 30 | B32: Labh Niwas & Subh Niwas CHSL | C32: Ghatkopar | D32: SP | E32: Slow Cooking | F32: Ashok Borana | G32: Redevelopment | I32: 1899.5 | J32: 4.05 | K32: 33(19)
A33: =A32+1 -> 31 | B33: Laxminarayan & Devlok & Devdeep (new) | C33: Santacruz W | D33: Vineet | E33: Active | F33: Sameer Sata | G33: Redevelopment | H33: Maps | I33: 2045.85 | J33: 2.97 | K33: 33(7B)
A34: =A33+1 -> 32 | B34: VIP | C34: Vile Parle East | D34: Vineet | E34: Hot | G34: Redevelopment | H34: Maps | I34: 909.2 | J34: 3.04 | K34: 30(A) + 20(B)
A35: =A34+1 -> 33 | B35: Bandstand Apartments | C35: Bandra | D35: Sahil | E35: To be figured | G35: Redevelopment | I35: 1749
A36: =A35+1 -> 34 | B36: Jayshree Apartments | C36: Worli | D36: Vineet | E36: Active | F36: Cheetak | G36: JV/JD | H36: Maps | I36: 1672 | J36: 5.4 | K36: 30(A)+20(B)
A37: =A36+1 -> 35 | B37: Lokhandwala Cluster | C37: Andheri W | D37: Shali | E37: Active | F37: Ashok Borana | G37: Redevelopment | I37: -
A38: =A37+1 -> 36 | B38: New Haven | C38: Andheri W | D38: SP | E38: Active | F38: Vinay | I38: 2252
A39: =A38+1 -> 37 | B39: Om Niwas | C39: Kurla | D39: Vineet | E39: Active | F39: Ashok Borana | G39: outright | I39: 2885 | J39: 5.4 | K39: 30(A)+20(B)
A40: =A39+1 -> 38 | B40: Rajiv CHS | C40: Bandra East | D40: Sagar | E40: Active | G40: Redevelopment | H40: Maps | I40: 1787 | K40: 33(7B) +20(B)
A41: =A40+1 -> 39 | B41: Goshala road Cluster | C41: Mulund W | D41: SP | E41: Won | F41: Ashok Borana | G41: Redevelopment | I41: 3394.3 | J41: 5.4 | K41: 33(7B) + 33(20B)
A42: =A41+1 -> 40 | B42: Ram Laxman Kutir | C42: Andehri | D42: Sagar | E42: Active | G42: Redevelopment | H42: Maps | I42: 5099 | J42: 4.05 | K42: 33(11)
A43: =A42+1 -> 41 | B43: Redstone | C43: Juhu | D43: Vineet | E43: Active | F43: Himanshu | G43: Redevelopment | I43: -
...

Sheet Hot Tracker
G1: x | H1: o | I1: ☑ | J1: S | K1: i
G2: Declined | H2: Sent | I2: EOI Rec. | J2: To be Sent | K2: interested
B4: Pipeline
B5: Status | D5: PoC - 1 | E5: PoC - 2 | F5: Runwal - Sandeep | G5: Runwal - Subodh | H5: Sobha | I5: L&T | J5: Mahindra | K5: HOH | L5: Kolte Patil | M5: Sattva | N5: Ramky | O5: Crest | P5: Prescon | Q5: NCC | R5: Sunteck | S5: VKG | T5: Kabra | U5: Raymond | V5: SKS Anchor Point | W5: Moongipa | X5: Kanakia | Y5: H.rishabhraj | Z5: Aditya Birla | AA5: Veena | AB5: DGS | AC5: K Raheja | AD5: Matrix | AE5: Kohinoor | AF5: Greenscape | AG5: Sonal | AH5: Q group | AI5: Raheja Homes | AJ5: Silver | AK5: Bluekey realty | AL5: Arkade | AM5: Lloyds | AN5: Sugee | AO5: Aditya Raj | AP5: Pushpa Raj | AQ5: Mass Group | AR5: Sumukha | AS5: Arth | AT5: Sai | AU5: Om | AV5: Mohite | AW5: Tater World | AX5: AVSN | AY5: B-right | AZ5: Puri Creators | BA5: Paradigm | BB5: Maniar | BC5: Agami | BD5: K Nagpal | BE5: Piramal | BF5: Kalpataru | BG5: Sheth | BH5: Tribeca | BI5: Supreme | BJ5: Woodstock
C6: Anand Nagar Santacruz | F6: =INDEX('Proposal Tracker'!$1:$1048576,MATCH('Hot Tracker'!$C6,'Proposal Tracker'!$C:$C,0),MATCH('Hot Tracker'!F$5,'Proposal Tracker'!$4:$4,0)) -> 0 | G6: =INDEX('Proposal Tracker'!$1:$1048576,MATCH('Hot Tracker'!$C6,'Proposal Tracker'!$C:$C,0),MATCH('Hot Tracker'!G$5,'Proposal Tracker'!$4:$4,0)) -> 0 | H6: =INDEX('Proposal Tracker'!$1:$1048576,MATCH('Hot Tracker'!$C6,'Proposal Tracker'!$C:$C,0),MATCH('Hot Tracker'!H$5,'Proposal Tracker'!$4:$4,0)) -> 0 | I6: =INDEX('Proposal Tracker'!$1:$1048576,MATCH('Hot Tracker'!$C6,'Proposal Tracker'!$C:$C,0),MATCH('Hot Tracker'!I$5,'Proposal Tracker'!$4:$4,0)) -> 0 | J6: =INDEX('Proposal Tracker'!$1:$1048576,MATCH('Hot Tracker'!$C6,'Proposal Tracker'!$C:$C,0),MATCH('Hot Tracker'!J$5,'Proposal Tracker'!$4:$4,0)) -> 0 | K6: =INDEX('Proposal Tracker'!$1:$1048576,MATCH('Hot Tracker'!$C6,'Proposal Tracker'!$C:$C,0),MATCH('Hot Tracker'!K$5,'Proposal Tracker'!$4:$4,0)) -> 0 | L6: =INDEX('Proposal Tracker'!$1:$1048576,MATCH('Hot Tracker'!$C6,'Proposal Tracker'!$C:$C,0),MATCH('Hot Tracker'!L$5,'Proposal Tracker'!$4:$4,0)) -> 0 | M6: =INDEX('Proposal Tracker'!$1:$1048576,MATCH('Hot Tracker'!$C6,'Proposal Tracker'!$C:$C,0),MATCH('Hot Tracker'!M$5,'Proposal Tracker'!$4:$4,0)) -> 0 | ... BJ6: =INDEX('Proposal Tracker'!$1:$1048576,MATCH('Hot Tracker'!$C6,'Proposal Tracker'!$C:$C,0),MATCH('Hot Tracker'!BJ$5,'Proposal Tracker'!$4:$4,0)) -> 0
C7: Borla | F7: =INDEX('Proposal Tracker'!$1:$1048576,MATCH('Hot Tracker'!$C7,'Proposal Tracker'!$C:$C,0),MATCH('Hot Tracker'!F$5,'Proposal Tracker'!$4:$4,0)) -> 0 | G7: =INDEX('Proposal Tracker'!$1:$1048576,MATCH('Hot Tracker'!$C7,'Proposal Tracker'!$C:$C,0),MATCH('Hot Tracker'!G$5,'Proposal Tracker'!$4:$4,0)) -> 0 | H7: =INDEX('Proposal Tracker'!$1:$1048576,MATCH('Hot Tracker'!$C7,'Proposal Tracker'!$C:$C,0),MATCH('Hot Tracker'!H$5,'Proposal Tracker'!$4:$4,0)) -> ☑ | I7: =INDEX('Proposal Tracker'!$1:$1048576,MATCH('Hot Tracker'!$C7,'Proposal Tracker'!$C:$C,0),MATCH('Hot Tracker'!I$5,'Proposal Tracker'!$4:$4,0)) -> o | J7: =INDEX('Proposal Tracker'!$1:$1048576,MATCH('Hot Tracker'!$C7,'Proposal Tracker'!$C:$C,0),MATCH('Hot Tracker'!J$5,'Proposal Tracker'!$4:$4,0)) -> o | K7: =INDEX('Proposal Tracker'!$1:$1048576,MATCH('Hot Tracker'!$C7,'Proposal Tracker'!$C:$C,0),MATCH('Hot Tracker'!K$5,'Proposal Tracker'!$4:$4,0)) -> X | L7: =INDEX('Proposal Tracker'!$1:$1048576,MATCH('Hot Tracker'!$C7,'Proposal Tracker'!$C:$C,0),MATCH('Hot Tracker'!L$5,'Proposal Tracker'!$4:$4,0)) -> X | M7: =INDEX('Proposal Tracker'!$1:$1048576,MATCH('Hot Tracker'!$C7,'Proposal Tracker'!$C:$C,0),MATCH('Hot Tracker'!M$5,'Proposal Tracker'!$4:$4,0)) -> X | ... BJ7: =INDEX('Proposal Tracker'!$1:$1048576,MATCH('Hot Tracker'!$C7,'Proposal Tracker'!$C:$C,0),MATCH('Hot Tracker'!BJ$5,'Proposal Tracker'!$4:$4,0)) -> 0
C8: Khajuria Nagar | F8: =INDEX('Proposal Tracker'!$1:$1048576,MATCH('Hot Tracker'!$C8,'Proposal Tracker'!$C:$C,0),MATCH('Hot Tracker'!F$5,'Proposal Tracker'!$4:$4,0)) -> o | G8: =INDEX('Proposal Tracker'!$1:$1048576,MATCH('Hot Tracker'!$C8,'Proposal Tracker'!$C:$C,0),MATCH('Hot Tracker'!G$5,'Proposal Tracker'!$4:$4,0)) -> o | H8: =INDEX('Proposal Tracker'!$1:$1048576,MATCH('Hot Tracker'!$C8,'Proposal Tracker'!$C:$C,0),MATCH('Hot Tracker'!H$5,'Proposal Tracker'!$4:$4,0)) -> 0 | I8: =INDEX('Proposal Tracker'!$1:$1048576,MATCH('Hot Tracker'!$C8,'Proposal Tracker'!$C:$C,0),MATCH('Hot Tracker'!I$5,'Proposal Tracker'!$4:$4,0)) -> S | J8: =INDEX('Proposal Tracker'!$1:$1048576,MATCH('Hot Tracker'!$C8,'Proposal Tracker'!$C:$C,0),MATCH('Hot Tracker'!J$5,'Proposal Tracker'!$4:$4,0)) -> S | K8: =INDEX('Proposal Tracker'!$1:$1048576,MATCH('Hot Tracker'!$C8,'Proposal Tracker'!$C:$C,0),MATCH('Hot Tracker'!K$5,'Proposal Tracker'!$4:$4,0)) -> S | L8: =INDEX('Proposal Tracker'!$1:$1048576,MATCH('Hot Tracker'!$C8,'Proposal Tracker'!$C:$C,0),MATCH('Hot Tracker'!L$5,'Proposal Tracker'!$4:$4,0)) -> S | M8: =INDEX('Proposal Tracker'!$1:$1048576,MATCH('Hot Tracker'!$C8,'Proposal Tracker'!$C:$C,0),MATCH('Hot Tracker'!M$5,'Proposal Tracker'!$4:$4,0)) -> 0 | ... BJ8: =INDEX('Proposal Tracker'!$1:$1048576,MATCH('Hot Tracker'!$C8,'Proposal Tracker'!$C:$C,0),MATCH('Hot Tracker'!BJ$5,'Proposal Tracker'!$4:$4,0)) -> 0
C9: New Jal Darshan | F9: =INDEX('Proposal Tracker'!$1:$1048576,MATCH('Hot Tracker'!$C9,'Proposal Tracker'!$C:$C,0),MATCH('Hot Tracker'!F$5,'Proposal Tracker'!$4:$4,0)) -> 0 | G9: =INDEX('Proposal Tracker'!$1:$1048576,MATCH('Hot Tracker'!$C9,'Proposal Tracker'!$C:$C,0),MATCH('Hot Tracker'!G$5,'Proposal Tracker'!$4:$4,0)) -> i | H9: =INDEX('Proposal Tracker'!$1:$1048576,MATCH('Hot Tracker'!$C9,'Proposal Tracker'!$C:$C,0),MATCH('Hot Tracker'!H$5,'Proposal Tracker'!$4:$4,0)) -> S | I9: =INDEX('Proposal Tracker'!$1:$1048576,MATCH('Hot Tracker'!$C9,'Proposal Tracker'!$C:$C,0),MATCH('Hot Tracker'!I$5,'Proposal Tracker'!$4:$4,0)) -> o | J9: =INDEX('Proposal Tracker'!$1:$1048576,MATCH('Hot Tracker'!$C9,'Proposal Tracker'!$C:$C,0),MATCH('Hot Tracker'!J$5,'Proposal Tracker'!$4:$4,0)) -> S | K9: =INDEX('Proposal Tracker'!$1:$1048576,MATCH('Hot Tracker'!$C9,'Proposal Tracker'!$C:$C,0),MATCH('Hot Tracker'!K$5,'Proposal Tracker'!$4:$4,0)) -> S | L9: =INDEX('Proposal Tracker'!$1:$1048576,MATCH('Hot Tracker'!$C9,'Proposal Tracker'!$C:$C,0),MATCH('Hot Tracker'!L$5,'Proposal Tracker'!$4:$4,0)) -> S | M9: =INDEX('Proposal Tracker'!$1:$1048576,MATCH('Hot Tracker'!$C9,'Proposal Tracker'!$C:$C,0),MATCH('Hot Tracker'!M$5,'Proposal Tracker'!$4:$4,0)) -> S | ... BJ9: =INDEX('Proposal Tracker'!$1:$1048576,MATCH('Hot Tracker'!$C9,'Proposal Tracker'!$C:$C,0),MATCH('Hot Tracker'!BJ$5,'Proposal Tracker'!$4:$4,0)) -> 0
C10: Nityanand Baug | F10: =INDEX('Proposal Tracker'!$1:$1048576,MATCH('Hot Tracker'!$C10,'Proposal Tracker'!$C:$C,0),MATCH('Hot Tracker'!F$5,'Proposal Tracker'!$4:$4,0)) -> 0 | G10: =INDEX('Proposal Tracker'!$1:$1048576,MATCH('Hot Tracker'!$C10,'Proposal Tracker'!$C:$C,0),MATCH('Hot Tracker'!G$5,'Proposal Tracker'!$4:$4,0)) -> x | H10: =INDEX('Proposal Tracker'!$1:$1048576,MATCH('Hot Tracker'!$C10,'Proposal Tracker'!$C:$C,0),MATCH('Hot Tracker'!H$5,'Proposal Tracker'!$4:$4,0)) -> o | I10: =INDEX('Proposal Tracker'!$1:$1048576,MATCH('Hot Tracker'!$C10,'Proposal Tracker'!$C:$C,0),MATCH('Hot Tracker'!I$5,'Proposal Tracker'!$4:$4,0)) -> o | J10: =INDEX('Proposal Tracker'!$1:$1048576,MATCH('Hot Tracker'!$C10,'Proposal Tracker'!$C:$C,0),MATCH('Hot Tracker'!J$5,'Proposal Tracker'!$4:$4,0)) -> o | K10: =INDEX('Proposal Tracker'!$1:$1048576,MATCH('Hot Tracker'!$C10,'Proposal Tracker'!$C:$C,0),MATCH('Hot Tracker'!K$5,'Proposal Tracker'!$4:$4,0)) -> S | L10: =INDEX('Proposal Tracker'!$1:$1048576,MATCH('Hot Tracker'!$C10,'Proposal Tracker'!$C:$C,0),MATCH('Hot Tracker'!L$5,'Proposal Tracker'!$4:$4,0)) -> i | M10: =INDEX('Proposal Tracker'!$1:$1048576,MATCH('Hot Tracker'!$C10,'Proposal Tracker'!$C:$C,0),MATCH('Hot Tracker'!M$5,'Proposal Tracker'!$4:$4,0)) -> X | ... BJ10: =INDEX('Proposal Tracker'!$1:$1048576,MATCH('Hot Tracker'!$C10,'Proposal Tracker'!$C:$C,0),MATCH('Hot Tracker'!BJ$5,'Proposal Tracker'!$4:$4,0)) -> 0
C11: Prahlad CHSL - Santacurz | F11: =INDEX('Proposal Tracker'!$1:$1048576,MATCH('Hot Tracker'!$C11,'Proposal Tracker'!$C:$C,0),MATCH('Hot Tracker'!F$5,'Proposal Tracker'!$4:$4,0)) -> 0 | G11: =INDEX('Proposal Tracker'!$1:$1048576,MATCH('Hot Tracker'!$C11,'Proposal Tracker'!$C:$C,0),MATCH('Hot Tracker'!G$5,'Proposal Tracker'!$4:$4,0)) -> 0 | H11: =INDEX('Proposal Tracker'!$1:$1048576,MATCH('Hot Tracker'!$C11,'Proposal Tracker'!$C:$C,0),MATCH('Hot Tracker'!H$5,'Proposal Tracker'!$4:$4,0)) -> o | I11: =INDEX('Proposal Tracker'!$1:$1048576,MATCH('Hot Tracker'!$C11,'Proposal Tracker'!$C:$C,0),MATCH('Hot Tracker'!I$5,'Proposal Tracker'!$4:$4,0)) -> o | J11: =INDEX('Proposal Tracker'!$1:$1048576,MATCH('Hot Tracker'!$C11,'Proposal Tracker'!$C:$C,0),MATCH('Hot Tracker'!J$5,'Proposal Tracker'!$4:$4,0)) -> 0 | K11: =INDEX('Proposal Tracker'!$1:$1048576,MATCH('Hot Tracker'!$C11,'Proposal Tracker'!$C:$C,0),MATCH('Hot Tracker'!K$5,'Proposal Tracker'!$4:$4,0)) -> S | L11: =INDEX('Proposal Tracker'!$1:$1048576,MATCH('Hot Tracker'!$C11,'Proposal Tracker'!$C:$C,0),MATCH('Hot Tracker'!L$5,'Proposal Tracker'!$4:$4,0)) -> S | M11: =INDEX('Proposal Tracker'!$1:$1048576,MATCH('Hot Tracker'!$C11,'Proposal Tracker'!$C:$C,0),MATCH('Hot Tracker'!M$5,'Proposal Tracker'!$4:$4,0)) -> S | ... BJ11: =INDEX('Proposal Tracker'!$1:$1048576,MATCH('Hot Tracker'!$C11,'Proposal Tracker'!$C:$C,0),MATCH('Hot Tracker'!BJ$5,'Proposal Tracker'!$4:$4,0)) -> 0
C12: Rajendra Park & Nalanda Mall, Goregaon (West) | F12: =INDEX('Proposal Tracker'!$1:$1048576,MATCH('Hot Tracker'!$C12,'Proposal Tracker'!$C:$C,0),MATCH('Hot Tracker'!F$5,'Proposal Tracker'!$4:$4,0)) -> i | G12: =INDEX('Proposal Tracker'!$1:$1048576,MATCH('Hot Tracker'!$C12,'Proposal Tracker'!$C:$C,0),MATCH('Hot Tracker'!G$5,'Proposal Tracker'!$4:$4,0)) -> o | H12: =INDEX('Proposal Tracker'!$1:$1048576,MATCH('Hot Tracker'!$C12,'Proposal Tracker'!$C:$C,0),MATCH('Hot Tracker'!H$5,'Proposal Tracker'!$4:$4,0)) -> 0 | I12: =INDEX('Proposal Tracker'!$1:$1048576,MATCH('Hot Tracker'!$C12,'Proposal Tracker'!$C:$C,0),MATCH('Hot Tracker'!I$5,'Proposal Tracker'!$4:$4,0)) -> 0 | J12: =INDEX('Proposal Tracker'!$1:$1048576,MATCH('Hot Tracker'!$C12,'Proposal Tracker'!$C:$C,0),MATCH('Hot Tracker'!J$5,'Proposal Tracker'!$4:$4,0)) -> X | K12: =INDEX('Proposal Tracker'!$1:$1048576,MATCH('Hot Tracker'!$C12,'Proposal Tracker'!$C:$C,0),MATCH('Hot Tracker'!K$5,'Proposal Tracker'!$4:$4,0)) -> 0 | L12: =INDEX('Proposal Tracker'!$1:$1048576,MATCH('Hot Tracker'!$C12,'Proposal Tracker'!$C:$C,0),MATCH('Hot Tracker'!L$5,'Proposal Tracker'!$4:$4,0)) -> o | M12: =INDEX('Proposal Tracker'!$1:$1048576,MATCH('Hot Tracker'!$C12,'Proposal Tracker'!$C:$C,0),MATCH('Hot Tracker'!M$5,'Proposal Tracker'!$4:$4,0)) -> x | ... BJ12: =INDEX('Proposal Tracker'!$1:$1048576,MATCH('Hot Tracker'!$C12,'Proposal Tracker'!$C:$C,0),MATCH('Hot Tracker'!BJ$5,'Proposal Tracker'!$4:$4,0)) -> 0
C13: Shree Ram CHSL, Andheri (West) | F13: =INDEX('Proposal Tracker'!$1:$1048576,MATCH('Hot Tracker'!$C13,'Proposal Tracker'!$C:$C,0),MATCH('Hot Tracker'!F$5,'Proposal Tracker'!$4:$4,0)) -> 0 | G13: =INDEX('Proposal Tracker'!$1:$1048576,MATCH('Hot Tracker'!$C13,'Proposal Tracker'!$C:$C,0),MATCH('Hot Tracker'!G$5,'Proposal Tracker'!$4:$4,0)) -> 0 | H13: =INDEX('Proposal Tracker'!$1:$1048576,MATCH('Hot Tracker'!$C13,'Proposal Tracker'!$C:$C,0),MATCH('Hot Tracker'!H$5,'Proposal Tracker'!$4:$4,0)) -> 0 | I13: =INDEX('Proposal Tracker'!$1:$1048576,MATCH('Hot Tracker'!$C13,'Proposal Tracker'!$C:$C,0),MATCH('Hot Tracker'!I$5,'Proposal Tracker'!$4:$4,0)) -> i | J13: =INDEX('Proposal Tracker'!$1:$1048576,MATCH('Hot Tracker'!$C13,'Proposal Tracker'!$C:$C,0),MATCH('Hot Tracker'!J$5,'Proposal Tracker'!$4:$4,0)) -> S | K13: =INDEX('Proposal Tracker'!$1:$1048576,MATCH('Hot Tracker'!$C13,'Proposal Tracker'!$C:$C,0),MATCH('Hot Tracker'!K$5,'Proposal Tracker'!$4:$4,0)) -> ? | L13: =INDEX('Proposal Tracker'!$1:$1048576,MATCH('Hot Tracker'!$C13,'Proposal Tracker'!$C:$C,0),MATCH('Hot Tracker'!L$5,'Proposal Tracker'!$4:$4,0)) -> ☑ | M13: =INDEX('Proposal Tracker'!$1:$1048576,MATCH('Hot Tracker'!$C13,'Proposal Tracker'!$C:$C,0),MATCH('Hot Tracker'!M$5,'Proposal Tracker'!$4:$4,0)) -> i | ... BJ13: =INDEX('Proposal Tracker'!$1:$1048576,MATCH('Hot Tracker'!$C13,'Proposal Tracker'!$C:$C,0),MATCH('Hot Tracker'!BJ$5,'Proposal Tracker'!$4:$4,0)) -> 0
C14: Sumer Nagar | F14: =INDEX('Proposal Tracker'!$1:$1048576,MATCH('Hot Tracker'!$C14,'Proposal Tracker'!$C:$C,0),MATCH('Hot Tracker'!F$5,'Proposal Tracker'!$4:$4,0)) -> i | G14: =INDEX('Proposal Tracker'!$1:$1048576,MATCH('Hot Tracker'!$C14,'Proposal Tracker'!$C:$C,0),MATCH('Hot Tracker'!G$5,'Proposal Tracker'!$4:$4,0)) -> o | H14: =INDEX('Proposal Tracker'!$1:$1048576,MATCH('Hot Tracker'!$C14,'Proposal Tracker'!$C:$C,0),MATCH('Hot Tracker'!H$5,'Proposal Tracker'!$4:$4,0)) -> o | I14: =INDEX('Proposal Tracker'!$1:$1048576,MATCH('Hot Tracker'!$C14,'Proposal Tracker'!$C:$C,0),MATCH('Hot Tracker'!I$5,'Proposal Tracker'!$4:$4,0)) -> o | J14: =INDEX('Proposal Tracker'!$1:$1048576,MATCH('Hot Tracker'!$C14,'Proposal Tracker'!$C:$C,0),MATCH('Hot Tracker'!J$5,'Proposal Tracker'!$4:$4,0)) -> o | K14: =INDEX('Proposal Tracker'!$1:$1048576,MATCH('Hot Tracker'!$C14,'Proposal Tracker'!$C:$C,0),MATCH('Hot Tracker'!K$5,'Proposal Tracker'!$4:$4,0)) -> X | L14: =INDEX('Proposal Tracker'!$1:$1048576,MATCH('Hot Tracker'!$C14,'Proposal Tracker'!$C:$C,0),MATCH('Hot Tracker'!L$5,'Proposal Tracker'!$4:$4,0)) -> o | M14: =INDEX('Proposal Tracker'!$1:$1048576,MATCH('Hot Tracker'!$C14,'Proposal Tracker'!$C:$C,0),MATCH('Hot Tracker'!M$5,'Proposal Tracker'!$4:$4,0)) -> i | ... BJ14: =INDEX('Proposal Tracker'!$1:$1048576,MATCH('Hot Tracker'!$C14,'Proposal Tracker'!$C:$C,0),MATCH('Hot Tracker'!BJ$5,'Proposal Tracker'!$4:$4,0)) -> 0
C15: Tolaram | F15: =INDEX('Proposal Tracker'!$1:$1048576,MATCH('Hot Tracker'!$C15,'Proposal Tracker'!$C:$C,0),MATCH('Hot Tracker'!F$5,'Proposal Tracker'!$4:$4,0)) -> 0 | G15: =INDEX('Proposal Tracker'!$1:$1048576,MATCH('Hot Tracker'!$C15,'Proposal Tracker'!$C:$C,0),MATCH('Hot Tracker'!G$5,'Proposal Tracker'!$4:$4,0)) -> i | H15: =INDEX('Proposal Tracker'!$1:$1048576,MATCH('Hot Tracker'!$C15,'Proposal Tracker'!$C:$C,0),MATCH('Hot Tracker'!H$5,'Proposal Tracker'!$4:$4,0)) -> o | I15: =INDEX('Proposal Tracker'!$1:$1048576,MATCH('Hot Tracker'!$C15,'Proposal Tracker'!$C:$C,0),MATCH('Hot Tracker'!I$5,'Proposal Tracker'!$4:$4,0)) -> o | J15: =INDEX('Proposal Tracker'!$1:$1048576,MATCH('Hot Tracker'!$C15,'Proposal Tracker'!$C:$C,0),MATCH('Hot Tracker'!J$5,'Proposal Tracker'!$4:$4,0)) -> o | K15: =INDEX('Proposal Tracker'!$1:$1048576,MATCH('Hot Tracker'!$C15,'Proposal Tracker'!$C:$C,0),MATCH('Hot Tracker'!K$5,'Proposal Tracker'!$4:$4,0)) -> 0 | L15: =INDEX('Proposal Tracker'!$1:$1048576,MATCH('Hot Tracker'!$C15,'Proposal Tracker'!$C:$C,0),MATCH('Hot Tracker'!L$5,'Proposal Tracker'!$4:$4,0)) -> o | M15: =INDEX('Proposal Tracker'!$1:$1048576,MATCH('Hot Tracker'!$C15,'Proposal Tracker'!$C:$C,0),MATCH('Hot Tracker'!M$5,'Proposal Tracker'!$4:$4,0)) -> X | ... BJ15: =INDEX('Proposal Tracker'!$1:$1048576,MATCH('Hot Tracker'!$C15,'Proposal Tracker'!$C:$C,0),MATCH('Hot Tracker'!BJ$5,'Proposal Tracker'!$4:$4,0)) -> 0
C16: Redstone, Juhu | F16: =INDEX('Proposal Tracker'!$1:$1048576,MATCH('Hot Tracker'!$C16,'Proposal Tracker'!$C:$C,0),MATCH('Hot Tracker'!F$5,'Proposal Tracker'!$4:$4,0)) -> x | G16: =INDEX('Proposal Tracker'!$1:$1048576,MATCH('Hot Tracker'!$C16,'Proposal Tracker'!$C:$C,0),MATCH('Hot Tracker'!G$5,'Proposal Tracker'!$4:$4,0)) -> x | H16: =INDEX('Proposal Tracker'!$1:$1048576,MATCH('Hot Tracker'!$C16,'Proposal Tracker'!$C:$C,0),MATCH('Hot Tracker'!H$5,'Proposal Tracker'!$4:$4,0)) -> 0 | I16: =INDEX('Proposal Tracker'!$1:$1048576,MATCH('Hot Tracker'!$C16,'Proposal Tracker'!$C:$C,0),MATCH('Hot Tracker'!I$5,'Proposal Tracker'!$4:$4,0)) -> 0 | J16: =INDEX('Proposal Tracker'!$1:$1048576,MATCH('Hot Tracker'!$C16,'Proposal Tracker'!$C:$C,0),MATCH('Hot Tracker'!J$5,'Proposal Tracker'!$4:$4,0)) -> 0 | K16: =INDEX('Proposal Tracker'!$1:$1048576,MATCH('Hot Tracker'!$C16,'Proposal Tracker'!$C:$C,0),MATCH('Hot Tracker'!K$5,'Proposal Tracker'!$4:$4,0)) -> x | L16: =INDEX('Proposal Tracker'!$1:$1048576,MATCH('Hot Tracker'!$C16,'Proposal Tracker'!$C:$C,0),MATCH('Hot Tracker'!L$5,'Proposal Tracker'!$4:$4,0)) -> i | M16: =INDEX('Proposal Tracker'!$1:$1048576,MATCH('Hot Tracker'!$C16,'Proposal Tracker'!$C:$C,0),MATCH('Hot Tracker'!M$5,'Proposal Tracker'!$4:$4,0)) -> i | ... BJ16: =INDEX('Proposal Tracker'!$1:$1048576,MATCH('Hot Tracker'!$C16,'Proposal Tracker'!$C:$C,0),MATCH('Hot Tracker'!BJ$5,'Proposal Tracker'!$4:$4,0)) -> 0
C17: Nalanda Malad | F17: =INDEX('Proposal Tracker'!$1:$1048576,MATCH('Hot Tracker'!$C17,'Proposal Tracker'!$C:$C,0),MATCH('Hot Tracker'!F$5,'Proposal Tracker'!$4:$4,0)) -> 0 | G17: =INDEX('Proposal Tracker'!$1:$1048576,MATCH('Hot Tracker'!$C17,'Proposal Tracker'!$C:$C,0),MATCH('Hot Tracker'!G$5,'Proposal Tracker'!$4:$4,0)) -> 0 | H17: =INDEX('Proposal Tracker'!$1:$1048576,MATCH('Hot Tracker'!$C17,'Proposal Tracker'!$C:$C,0),MATCH('Hot Tracker'!H$5,'Proposal Tracker'!$4:$4,0)) -> 0 | I17: =INDEX('Proposal Tracker'!$1:$1048576,MATCH('Hot Tracker'!$C17,'Proposal Tracker'!$C:$C,0),MATCH('Hot Tracker'!I$5,'Proposal Tracker'!$4:$4,0)) -> 0 | J17: =INDEX('Proposal Tracker'!$1:$1048576,MATCH('Hot Tracker'!$C17,'Proposal Tracker'!$C:$C,0),MATCH('Hot Tracker'!J$5,'Proposal Tracker'!$4:$4,0)) -> 0 | K17: =INDEX('Proposal Tracker'!$1:$1048576,MATCH('Hot Tracker'!$C17,'Proposal Tracker'!$C:$C,0),MATCH('Hot Tracker'!K$5,'Proposal Tracker'!$4:$4,0)) -> 0 | L17: =INDEX('Proposal Tracker'!$1:$1048576,MATCH('Hot Tracker'!$C17,'Proposal Tracker'!$C:$C,0),MATCH('Hot Tracker'!L$5,'Proposal Tracker'!$4:$4,0)) -> 0 | M17: =INDEX('Proposal Tracker'!$1:$1048576,MATCH('Hot Tracker'!$C17,'Proposal Tracker'!$C:$C,0),MATCH('Hot Tracker'!M$5,'Proposal Tracker'!$4:$4,0)) -> 0 | ... BJ17: =INDEX('Proposal Tracker'!$1:$1048576,MATCH('Hot Tracker'!$C17,'Proposal Tracker'!$C:$C,0),MATCH('Hot Tracker'!BJ$5,'Proposal Tracker'!$4:$4,0)) -> 0
... C25: LBS Marg - Outright | F25: =INDEX('Proposal Tracker'!$1:$1048576,MATCH('Hot Tracker'!$C25,'Proposal Tracker'!$C:$C,0),MATCH('Hot Tracker'!F$5,'Proposal Tracker'!$4:$4,0)) -> 0 | G25: =INDEX('Proposal Tracker'!$1:$1048576,MATCH('Hot Tracker'!$C25,'Proposal Tracker'!$C:$C,0),MATCH('Hot Tracker'!G$5,'Proposal Tracker'!$4:$4,0)) -> 0 | H25: =INDEX('Proposal Tracker'!$1:$1048576,MATCH('Hot Tracker'!$C25,'Proposal Tracker'!$C:$C,0),MATCH('Hot Tracker'!H$5,'Proposal Tracker'!$4:$4,0)) -> 0 | I25: =INDEX('Proposal Tracker'!$1:$1048576,MATCH('Hot Tracker'!$C25,'Proposal Tracker'!$C:$C,0),MATCH('Hot Tracker'!I$5,'Proposal Tracker'!$4:$4,0)) -> 0 | J25: =INDEX('Proposal Tracker'!$1:$1048576,MATCH('Hot Tracker'!$C25,'Proposal Tracker'!$C:$C,0),MATCH('Hot Tracker'!J$5,'Proposal Tracker'!$4:$4,0)) -> 0 | K25: =INDEX('Proposal Tracker'!$1:$1048576,MATCH('Hot Tracker'!$C25,'Proposal Tracker'!$C:$C,0),MATCH('Hot Tracker'!K$5,'Proposal Tracker'!$4:$4,0)) -> s | L25: =INDEX('Proposal Tracker'!$1:$1048576,MATCH('Hot Tracker'!$C25,'Proposal Tracker'!$C:$C,0),MATCH('Hot Tracker'!L$5,'Proposal Tracker'!$4:$4,0)) -> o | M25: =INDEX('Proposal Tracker'!$1:$1048576,MATCH('Hot Tracker'!$C25,'Proposal Tracker'!$C:$C,0),MATCH('Hot Tracker'!M$5,'Proposal Tracker'!$4:$4,0)) -> s | ... BJ25: =INDEX('Proposal Tracker'!$1:$1048576,MATCH('Hot Tracker'!$C25,'Proposal Tracker'!$C:$C,0),MATCH('Hot Tracker'!BJ$5,'Proposal Tracker'!$4:$4,0)) -> 0
B30: Opps list
B31: Type
B32: PMC | C32: Bandstand apartments
B33: PMC | C33: Jaywant
B34: PMC | C34: Greenfield - 3
B35: PMC | C35: Greenfield - Namaskar
B36: PMC | C36: Greenfield - Swagat
B37: PMC | C37: Sumer Nagar
B46: Won List
B47: Type
B48: PMC | C48: Ayodhaya
B49: PMC | C49: Triveni
B50: PMC | C50: NJD
B51: PMC | C51: Dudhsagar
B52: PMC | C52: Rajiv
B53: PMC | C53: Divya Jyot
B54: PMC | C54: Prahlad
B55: PMC | C55: Lokhandwala
B56: PMC | C56: Manish Nagar

Sheet List of Developers 
A1: Sr. No | B1: Developer | C1: Grade
B2: GRADE - A
A3: 1 | B3: Birla Estates | C3: A
A4: =A3+1 -> 2 | B4: Crest | C4: A
A5: =A4+1 -> 3 | B5: Greenscape | C5: A
A6: =A5+1 -> 4 | B6: House of Hiranandani | C6: A
A7: =A6+1 -> 5 | B7: K raheja Corp | C7: A
A8: =A7+1 -> 6 | B8: Kanakia | C8: A
A9: =A8+1 -> 7 | B9: Kolte patil | C9: A | D9: shadab.siddiqui@koltepatil.com
A10: =A9+1 -> 8 | B10: L&T Realty | C10: A
